# 1. 에러 처리의 필요성

에러가 발생하지 않는 코드를 작성하는 것은 불가능하다. 따라서 에러는 언제나 발생할 수 있다. **발생한 에러에 대해 대처하지 않고 방치하면 프로그램은 강제 종료된다**.

```javascript
console.log("[Start]");

foo(); // ReferenceError: foo is not defined
// 발생한 에러를 방치하면 프로그램은 강제 종료된다.

// 에러에 의해 프로그램이 강제 종료되어 아래 코드는 실행되지 않는다.
console.log("[End]");
```

`try...catch` 문을 사용해 발생한 에러에 적절하게 대응하면 프로그램이 강제 종료되지 않고 계속해서 코드를 실행시킬 수 있다.

```javascript
console.log("[Start]");

try {
  foo();
} catch (error) {
  console.error("[에러 발생]", error);
  // [에러 발생] ReferenceError: foo is not defined
}

// 발생한 에러에 적절한 대응을 하면 프로그램이 강제 종료되지 않는다.
console.log("[End]");
```

에러나 예외적인 상황에 대응하지 않으면 프로그램은 강제 종료될 것이다. 에러나 예외적인 상황은 너무나 다양하기 때문에 아무런 조치 없이 프로그램이 강제 종료된다면 원인을 파악하여 대응하기 어렵다.

에러가 발생하지 않는 코드를 작성하는 것이 이상적이지만 안타깝게도 그것은 불가능하다. 따라서 우리가 작성한 코드에서는 언제나 에러나 예외적인 상황이 발생할 수 있다는 것을 전제하고 이에 대응하는 코드를 작성하는 것이 중요하다.

# 2. try...catch...finally 문

기본적으로 에러 처리를 구현하는 방법은 크게 두가지가 있다. 예외적인 상황이 발생하면 반환하는 값(null 또는 -1)을 if문이나 단축 평가 또는 옵셔널 체이닝 연산자를 통해 확인해서 처리하는 방법과 에러 처리 코드를 미리 등록해 두고 에러가 발생하면 에러 처리 코드로 점프하도록 하는 방법이 있다.

`try...catch...finally` 문은 두 번째 방법이다. 일반적으로 이 방법을 에러 처리라고 한다. `try...catch...finally` 문은 다음과 같이 3개의 코드 블록으로 구성된다. finally 문은 불필요하다면 생략가능하다. catch 문도 생략 가능하지만 catch 문이 없는 try 문은 의미가 없으므로 생략하지 않는다.

```javascript
try {
  // 실행할 코드(에러가 발생할 가능성이 있는 코드)
} catch (err) {
  // try 코드 블록에서 에러가 발생하면 이 코드 블록의 코드가 실행된다.
  // err에는 try 코드 블록에서 발생한 Error 객체가 전달된다.
} finally {
  // 에러 발생과 상관없이 반드시 한 번 실행한다.
}
```

`try...catch...finally` 문을 실행하면 먼저 try 코드 블록이 실행된다. 이 때 try 코드 블록에 포함된 문 중에서 에러가 발생하면 발생한 에러는 catch 문의 err 변수에 전달되고 catch 코드 블록이 실행된다.

catch 문의 err 변수(변수 이름은 무엇이든 상관없다)는 try 코드 블록에 포함된 문 중에서 에러가 발생하면 생성되고 된 후에 catch 코드 블록에서만 유효하다.

finally 코드 블록은 에러 발생과 상관없이 반드시 한 번 실행된다. `try...catch...finally` 문으로 에러를 처리하면 프로그램이 강제 종료되지 않는다.

```javascript
console.log("[Start]");

try {
  // 실행한 코드(에러가 발생한 가능성이 있는 코드)
  foo();
} catch (err) {
  // try 코드 블록에서 에러가 발생하면 이 코드 블록의 코드가 실행한다.
  // err에는 try 코드 블록에서 발생한 Error 객체가 전달된다.
  console.error(err); // ReferenceError: foo is not defined
} finally {
  // 에러 발생과 상관없이 반드시 한 번 실행된다.
  console.log("finally");
}

// try...catch...finally 문으로 에러를 처리하면 프로그램이 강제 종료되지 않는다.
console.log("[End]");
```

# Error 객체

Error 생성자 함수는 에러 객체를 생성한다. Error 생성자 함수에는 에러를 상세히 설명하는 에러 메시지를 인수로 전달할 수 있다.

```javascript
const error = new Error("invalid");
```

# 4. throw 문

Error 생성자 함수로 에러 객체를 생성한다고 에러가 발생하는 것은 아니다. 즉 에러 객체 생성과 에러 발생의 의미는 다르다.

```javascript
try {
  // 에러 객체를 생성한다고 에러가 발생하는 것은 아니다.
  new Error("something wrong");
} catch (error) {
  console.log(error);
}
```

에러를 발생시키려면 try 코드 블록에서 throw 문으로 에러 객체를 던져야 한다.

```javascript
throw 표현식;
```

throw 문의 표현식은 어떤 값이라도 상관없지만 일반적으로 에러 객체를 지정한다. 에러를 던지면 catch 문의 에러 변수가 생성되고 던져진 에러 객체가 할당된다. 그리고 catch 코드 블록이 실행되기 시작한다.

```javascript
try {
  // 에러 객체를 던지면 catch 코드 블록이 실행되기 시작한다.
  throw new Error("something wrong");
} catch (error) {
  console.log(error);
}
```

# 5. 에러의 전파

에러는 호출자 방향으로 전파된다. 즉, 콜 스택의 아래 방향(실행 중인 실행 컨텍스트가 푸시되기 직전에 푸시된 실행 컨텍스트 방향)으로 전파된다.

```javascript
const foo = () => {
  throw Error("foo에서 발생한 에러"); // -- 4번
};

const bar = () => {
  foo(); // -- 3번
};

const baz = () => {
  bar(); // -- 2번
};

try {
  baz(); // -- 1번
} catch (err) {
  console.error(err);
}
```

1번에서 baz 함수를 호출하면 2번에서 bar 함수가 호출되고 3번에서 foo 함수가 호출되고 foo 함수는 4번에서 에러를 throw 한다. 이때 foo 함수가 throw한 에러는 다음과 같이 호출자에게 전파되어 전역에서 캐치된다.

<img width="351" alt="스크린샷 2022-04-14 오후 9 34 04" src="https://user-images.githubusercontent.com/71131248/163391827-c5b45da9-b59a-41b4-b63f-332021d22920.png">

이처럼 throw된 에러를 캐치하지 않으면 호출자 방향으로 전파된다. 이때 throw된 에러를 캐치하여 적절히 대응하면 프로그램을 강제 종료시키지 않고 코드이 실행 흐름을 복구할 수 있다. throw된 에러를 어디에서도 캐치하지 않으면 프로그램은 강제 종료된다.
